Mon Jul 28 00:49:12 UTC 2025 Thread[#37,RMI TCP Connection(4)-127.0.0.1,5,RMI Runtime] Cleanup action starting
java.sql.SQLException: Database '/Users/velocityworks/PycharmProjects/lightprimes/sandbox_d/prime_geometer.py' not found.
	at org.apache.derby.impl.jdbc.SQLExceptionFactory.getSQLException(SQLExceptionFactory.java:115)
	at org.apache.derby.impl.jdbc.SQLExceptionFactory.getSQLException(SQLExceptionFactory.java:141)
	at org.apache.derby.impl.jdbc.Util.generateCsSQLException(Util.java:225)
	at org.apache.derby.impl.jdbc.Util.generateCsSQLException(Util.java:220)
	at org.apache.derby.impl.jdbc.EmbedConnection.newSQLException(EmbedConnection.java:3208)
	at org.apache.derby.impl.jdbc.EmbedConnection.handleDBNotFound(EmbedConnection.java:767)
	at org.apache.derby.impl.jdbc.EmbedConnection.<init>(EmbedConnection.java:437)
	at org.apache.derby.iapi.jdbc.InternalDriver.getNewEmbedConnection(InternalDriver.java:629)
	at org.apache.derby.iapi.jdbc.InternalDriver.connect(InternalDriver.java:295)
	at org.apache.derby.iapi.jdbc.InternalDriver.connect(InternalDriver.java:921)
	at org.apache.derby.jdbc.EmbeddedDriver.connect(EmbeddedDriver.java:125)
	at com.intellij.database.remote.jdbc.helpers.JdbcHelperImpl.connect(JdbcHelperImpl.java:769)
	at com.intellij.database.remote.jdbc.impl.RemoteDriverImpl.connect(RemoteDriverImpl.java:152)
	at java.base/jdk.internal.reflect.DirectMethodHandleAccessor.invoke(DirectMethodHandleAccessor.java:103)
	at java.base/java.lang.reflect.Method.invoke(Method.java:580)
	at java.rmi/sun.rmi.server.UnicastServerRef.dispatch(UnicastServerRef.java:360)
	at java.rmi/sun.rmi.transport.Transport$1.run(Transport.java:200)
	at java.rmi/sun.rmi.transport.Transport$1.run(Transport.java:197)
	at java.base/java.security.AccessController.doPrivileged(AccessController.java:714)
	at java.rmi/sun.rmi.transport.Transport.serviceCall(Transport.java:196)
	at java.rmi/sun.rmi.transport.tcp.TCPTransport.handleMessages(TCPTransport.java:598)
	at java.rmi/sun.rmi.transport.tcp.TCPTransport$ConnectionHandler.run0(TCPTransport.java:844)
	at java.rmi/sun.rmi.transport.tcp.TCPTransport$ConnectionHandler.lambda$run$0(TCPTransport.java:721)
	at java.base/java.security.AccessController.doPrivileged(AccessController.java:400)
	at java.rmi/sun.rmi.transport.tcp.TCPTransport$ConnectionHandler.run(TCPTransport.java:720)
	at java.base/java.util.concurrent.ThreadPoolExecutor.runWorker(ThreadPoolExecutor.java:1144)
	at java.base/java.util.concurrent.ThreadPoolExecutor$Worker.run(ThreadPoolExecutor.java:642)
	at java.base/java.lang.Thread.run(Thread.java:1583)
Caused by: ERROR XJ004: Database '/Users/velocityworks/PycharmProjects/lightprimes/sandbox_d/prime_geometer.py' not found.
	at org.apache.derby.shared.common.error.StandardException.newException(StandardException.java:299)
	at org.apache.derby.impl.jdbc.SQLExceptionFactory.wrapArgsForTransportAcrossDRDA(SQLExceptionFactory.java:170)
	at org.apache.derby.impl.jdbc.SQLExceptionFactory.getSQLException(SQLExceptionFactory.java:75)
	... 27 more
============= begin nested exception, level (1) ===========
ERROR XJ004: Database '/Users/velocityworks/PycharmProjects/lightprimes/sandbox_d/prime_geometer.py' not found.
	at org.apache.derby.shared.common.error.StandardException.newException(StandardException.java:299)
	at org.apache.derby.impl.jdbc.SQLExceptionFactory.wrapArgsForTransportAcrossDRDA(SQLExceptionFactory.java:170)
	at org.apache.derby.impl.jdbc.SQLExceptionFactory.getSQLException(SQLExceptionFactory.java:75)
	at org.apache.derby.impl.jdbc.SQLExceptionFactory.getSQLException(SQLExceptionFactory.java:141)
	at org.apache.derby.impl.jdbc.Util.generateCsSQLException(Util.java:225)
	at org.apache.derby.impl.jdbc.Util.generateCsSQLException(Util.java:220)
	at org.apache.derby.impl.jdbc.EmbedConnection.newSQLException(EmbedConnection.java:3208)
	at org.apache.derby.impl.jdbc.EmbedConnection.handleDBNotFound(EmbedConnection.java:767)
	at org.apache.derby.impl.jdbc.EmbedConnection.<init>(EmbedConnection.java:437)
	at org.apache.derby.iapi.jdbc.InternalDriver.getNewEmbedConnection(InternalDriver.java:629)
	at org.apache.derby.iapi.jdbc.InternalDriver.connect(InternalDriver.java:295)
	at org.apache.derby.iapi.jdbc.InternalDriver.connect(InternalDriver.java:921)
	at org.apache.derby.jdbc.EmbeddedDriver.connect(EmbeddedDriver.java:125)
	at com.intellij.database.remote.jdbc.helpers.JdbcHelperImpl.connect(JdbcHelperImpl.java:769)
	at com.intellij.database.remote.jdbc.impl.RemoteDriverImpl.connect(RemoteDriverImpl.java:152)
	at java.base/jdk.internal.reflect.DirectMethodHandleAccessor.invoke(DirectMethodHandleAccessor.java:103)
	at java.base/java.lang.reflect.Method.invoke(Method.java:580)
	at java.rmi/sun.rmi.server.UnicastServerRef.dispatch(UnicastServerRef.java:360)
	at java.rmi/sun.rmi.transport.Transport$1.run(Transport.java:200)
	at java.rmi/sun.rmi.transport.Transport$1.run(Transport.java:197)
	at java.base/java.security.AccessController.doPrivileged(AccessController.java:714)
	at java.rmi/sun.rmi.transport.Transport.serviceCall(Transport.java:196)
	at java.rmi/sun.rmi.transport.tcp.TCPTransport.handleMessages(TCPTransport.java:598)
	at java.rmi/sun.rmi.transport.tcp.TCPTransport$ConnectionHandler.run0(TCPTransport.java:844)
	at java.rmi/sun.rmi.transport.tcp.TCPTransport$ConnectionHandler.lambda$run$0(TCPTransport.java:721)
	at java.base/java.security.AccessController.doPrivileged(AccessController.java:400)
	at java.rmi/sun.rmi.transport.tcp.TCPTransport$ConnectionHandler.run(TCPTransport.java:720)
	at java.base/java.util.concurrent.ThreadPoolExecutor.runWorker(ThreadPoolExecutor.java:1144)
	at java.base/java.util.concurrent.ThreadPoolExecutor$Worker.run(ThreadPoolExecutor.java:642)
	at java.base/java.lang.Thread.run(Thread.java:1583)
============= end nested exception, level (1) ===========
Cleanup action completed
